Workbook

Sheet Инструкция
B2: Модель TCO (Total Cost of Ownership) — кейс «Africa Delivery», горизонт 5 лет
B4: Зачем этот файл
B5: Задача | C5: Оценить полную стоимость владения выбранным архитектурным вариантом на 5 лет и использовать цифры как аргумент в ADR №1 («Выбор архитектурного стиля»).
B6: Как использовать | C6: Заполни один и тот же шаблон для каждого рассматриваемого варианта (например: модульный монолит / SOA / микросервисы) — сравнивать нужно итоги, а не ощущения.
B8: Цветовая легенда
B9: Синий текст на жёлтом фоне | C9: Ячейки для заполнения. Только их и редактируем.
B10: Чёрный текст | C10: Формулы. Не трогаем — пересчитаются сами.
B11: Зелёный текст | C11: Ссылка на лист «Допущения».
B13: Порядок работы
B14: Шаг 1 | C14: Лист «Допущения» → блок 1: вбить драйверы бизнеса по годам (активные пользователи, число заказов, средний чек). Из них считается GMV.
B15: Шаг 2 | C15: Лист «Допущения» → блок 2: финансовые допущения (инфляция, рост ФОТ, ставка дисконтирования, резерв, целевой SLO).
B16: Шаг 3 | C16: Лист «TCO» → в колонке «База, $/год (Год 1)» указать затраты первого года по каждой статье. Лишние статьи оставить пустыми, свои — дописать в свободные строки.
B17: Шаг 4 | C17: Лист «TCO» → в колонке «Драйвер роста» выбрать из выпадающего списка, от чего растёт статья: фикс / инфляция / ФОТ / пользователи / заказы / GMV. Годы 2–5 посчитаются сами.
B18: Шаг 5 | C18: Посмотреть блок «Ключевые метрики» внизу листа TCO и сводку на листе «Сводка». Лимит CFO - $5k/мес с SaaS (А6).
B20: Что важно не забыть в этом кейсе
B21: Бюджет CFO | C21: $5 000/мес на всё техническое с регулярными платежами, включая SaaS и мониторинг (А6). $9k - цифра из презентации совету, разработке недоступна.
B22: Цена простоя | C22: Инвестор оценивает минуту в $12 000 (А1). Это соответствует GMV $6,3 млрд в год. В модели потери считаются от фактического GMV года с пиковым коэффициентом.
B23: Транзакционные расходы | C23: Комиссии M-Pesa / Flutterwave / Paystack, SMS и WhatsApp растут с GMV и числом заказов и на горизонте 5 лет обычно обгоняют инфраструктуру. Не забудь их — это типичная ошибка.
B24: Сравнение вариантов | C24: Транзакционные расходы (блок 3) почти одинаковы для любой архитектуры — это pass-through от оборота. Варианты архитектуры сравнивай по блокам 1, 2, 4 и 6.
B25: Разовые затраты | C25: Комплаенс-аудит NDPR/POPIA, пентест, миграция — если статья возникает не каждый год, просто перезапиши формулу в нужной ячейке года числом (и покрась в синий).
B26: Люди | C26: ФОТ команды — обычно самая крупная статья TCO. Микросервисы дешевле в масштабировании, но дороже в эксплуатации: это должно быть видно в цифрах, а не только в тексте ADR.
B28: Все числа в файле — примеры для демонстрации формата. Замени их своими оценками и укажи источник в колонке «Комментарий / источник».

Sheet Сводка
B2: Сводка вариантов - TCO 5 лет, $
B4: Метрика | C4: V1 Модульный монолит | D4: V2 Сервисы на K8s | E4: V3 Микросервисы CTO | F4: Комментарий
B5: TCO 5 лет, прямые затраты | C5: ='TCO-V1'!E59 | D5: ='TCO-V2'!E59 | E5: ='TCO-V3'!E59 | F5: Основа сравнения
B6: TCO 5 лет с ожидаемыми потерями от простоя | C6: ='TCO-V1'!E60 | D6: ='TCO-V2'!E60 | E6: ='TCO-V3'!E60 | F6: Блок 6 от GMV
B7: NPV затрат 5 лет | C7: ='TCO-V1'!E61 | D7: ='TCO-V2'!E61 | E7: ='TCO-V3'!E61 | F7: Ставка 25%
B8: Блок 1. Облако, 5 лет | C8: ='TCO-V1'!J15 | D8: ='TCO-V2'!J15 | E8: ='TCO-V3'!J15
B9: Блок 2. Лицензии и SaaS, 5 лет | C9: ='TCO-V1'!J24 | D9: ='TCO-V2'!J24 | E9: ='TCO-V3'!J24
B10: Блок 3. Транзакционные, 5 лет | C10: ='TCO-V1'!J32 | D10: ='TCO-V2'!J32 | E10: ='TCO-V3'!J32 | F10: Одинаков для всех вариантов
B11: Блок 4. ФОТ, 5 лет | C11: ='TCO-V1'!J40 | D11: ='TCO-V2'!J40 | E11: ='TCO-V3'!J40 | F11: Главная разница
B12: Блок 5. Разовые и комплаенс, 5 лет | C12: ='TCO-V1'!J48 | D12: ='TCO-V2'!J48 | E12: ='TCO-V3'!J48
B13: Блок 6. Ожидаемые потери от простоя, 5 лет | C13: ='TCO-V1'!J53 | D13: ='TCO-V2'!J53 | E13: ='TCO-V3'!J53
B14: Облако, $/мес Год 1 | C14: ='TCO-V1'!E63 | D14: ='TCO-V2'!E63 | E14: ='TCO-V3'!E63
B15: Облако + SaaS, $/мес Год 1 | C15: ='TCO-V1'!E77 | D15: ='TCO-V2'!E77 | E15: ='TCO-V3'!E77 | F15: Лимит CFO $5 000 (А6)
B16: Проверка лимита CFO | C16: ='TCO-V1'!E78 | D16: ='TCO-V2'!E78 | E16: ='TCO-V3'!E78
B17: Сравнимая часть: блоки 1, 2, 4, 6, 5 лет | C17: ='TCO-V1'!J15+'TCO-V1'!J24+'TCO-V1'!J40+'TCO-V1'!J53 | D17: ='TCO-V2'!J15+'TCO-V2'!J24+'TCO-V2'!J40+'TCO-V2'!J53 | E17: ='TCO-V3'!J15+'TCO-V3'!J24+'TCO-V3'!J40+'TCO-V3'!J53 | F17: Блок 3 одинаков, сравнение по блокам 1, 2, 4, 6
B18: Минут простоя за 5 лет при целевом SLO | C18: =SUMPRODUCT(1-'TCO-V1'!E80:I80)*525600 | D18: =SUMPRODUCT(1-'TCO-V2'!E80:I80)*525600 | E18: =SUMPRODUCT(1-'TCO-V3'!E80:I80)*525600
B19: TCO на 1 заказ за 5 лет | C19: ='TCO-V1'!E65 | D19: ='TCO-V2'!E65 | E19: ='TCO-V3'!E65
B20: ИТ-затраты как доля GMV | C20: ='TCO-V1'!E67 | D20: ='TCO-V2'!E67 | E20: ='TCO-V3'!E67
B21: Доля ФОТ в TCO | C21: ='TCO-V1'!E70 | D21: ='TCO-V2'!E70 | E21: ='TCO-V3'!E70
B24: Стоимость ошибки: построили под 10M (V3), пришло 50k
B25: Год 1, блоки 1, 2, 4, 5 с резервом: V3 минус V1
B26: Год 1 без транзакционных, $ (V1 | V3) | C26: =('TCO-V1'!E15+'TCO-V1'!E24+'TCO-V1'!E40+'TCO-V1'!E48)*(1+Допущения!$C$17) | E26: =('TCO-V3'!E15+'TCO-V3'!E24+'TCO-V3'!E40+'TCO-V3'!E48)*(1+Допущения!$C$17)
B27: Потрачено впустую в Год 1, $ | C27: =E26-C26
B28: + невозвратная реклама при срыве 15.10 (А2), $ | C28: 180000
B29: Итого цена ошибки «строим большое», $ | C29: =C27+C28
B31: Обратная ошибка: построили V1, а рост быстрее плана
B32: Выделение 2-3 модулей в сервисы: 3 инженера × 4 мес × $5k, $ | C32: 60000
B33: Мультирегион на год раньше плана (Год 2 вместо Год 3), $ | C33: 120000
B34: Итого цена ошибки «строим малое», $ | C34: =C32+C33
B36: Точка безубыточности по цене минуты простоя
B37: При какой цене минуты дорогой вариант окупает себя меньшим простоем, $/мин | D37: =(('TCO-V2'!J15+'TCO-V2'!J24+'TCO-V2'!J40+'TCO-V2'!J48)-('TCO-V1'!J15+'TCO-V1'!J24+'TCO-V1'!J40+'TCO-V1'!J48))*(1+Допущения!$C$17)/(C18-D18) | E37: =(('TCO-V3'!J15+'TCO-V3'!J24+'TCO-V3'!J40+'TCO-V3'!J48)-('TCO-V1'!J15+'TCO-V1'!J24+'TCO-V1'!J40+'TCO-V1'!J48))*(1+Допущения!$C$17)/(C18-E18)
B38: Каждый вариант против V1. Инвестор: $12 000 (А1). Средний GMV в минуту: Год 1 $46, Год 5 $1 600

Sheet Допущения
B2: Допущения модели TCO — Africa Delivery
B3: Заполняются только ячейки с жёлтой заливкой. Все числа ниже — пример, заменить своими.
B5: 1. Драйверы бизнеса — заполнить
B6: Показатель | C6: Год 1 | D6: Год 2 | E6: Год 3 | F6: Год 4 | G6: Год 5 | H6: Комментарий / источник
B7: Активные пользователи (на конец года) | C7: 1000000 | D7: 2500000 | E7: 5000000 | F7: 7000000 | G7: 9000000 | H7: Цель 12 мес: 1M+ пользователей (ЦБ). Далее 12-15 стран к Год 3 (А1). Не 10M (А5)
B8: Число заказов в год | C8: 1200000 | D8: 6000000 | E8: 15000000 | F8: 25000000 | G8: 35000000 | H8: Месяц 1: ~20k заказов, месяц 12: ~250k заказов в месяц. Далее рост по странам
B9: Средний чек (AOV), $ | C9: 20 | D9: 21 | E9: 22 | F9: 23 | G9: 24 | H9: Ставка на низкую цену (ЦБ). Смартфоны дешевле $150 (А2)
B10: GMV, $ в год (расчёт) | C10: =C8*C9 | D10: =D8*D9 | E10: =E8*E9 | F10: =F8*F9 | G10: =G8*G9 | H10: Расчёт: заказы × средний чек
B12: 2. Финансовые допущения — заполнить
B13: Параметр | C13: Значение | H13: Комментарий / источник
B14: Инфляция затрат, % в год | C14: 0.08 | H14: Применяется к статьям с драйвером «инфляция»
B15: Рост ФОТ, % в год | C15: 0.1 | H15: Рост ставок контракторов
B16: Ставка дисконтирования, % в год | C16: 0.25 | H16: Runway 9 месяцев (А6): риск выше стандартного стартапа
B17: Резерв на непредвиденное (contingency), % | C17: 0.15 | H17: Надбавка к прямым затратам
B18: Бюджет CFO на облако, $/мес | C18: 5000 | H18: Жёсткий потолок на всё техническое, включая SaaS (А6). $9k - не для разработки
B19: Стоимость минуты простоя, $ | C19: 12000 | H19: Оценка инвестора (А1). Только справочно: соответствует GMV $6,3 млрд в год
B20: Целевой SLO (доступность), % | C20: 0.9999 | H20: Справочно. В расчёте используется SLO по годам на листе варианта (строка 80)
B21: Учитывать стоимость простоя в TCO (1 — да, 0 — нет) | C21: 1 | H21: Переключатель для сценарного анализа
B22: Пиковый коэффициент потерь при простое | C22: 3 | H22: Простой чаще случается в пик (распродажа, реклама): потери × 3 к среднему GMV/мин
B23: 3. Индексы роста — расчёт, не редактировать
B24: Драйвер | C24: Год 1 | D24: Год 2 | E24: Год 3 | F24: Год 4 | G24: Год 5 | H24: Как считается
B25: фикс | C25: 1 | D25: 1 | E25: 1 | F25: 1 | G25: 1 | H25: Затраты не меняются по годам
B26: инфляция | C26: 1 | D26: =C26*(1+$C$14) | E26: =D26*(1+$C$14) | F26: =E26*(1+$C$14) | G26: =F26*(1+$C$14) | H26: Год N = Год N-1 × (1 + инфляция)
B27: ФОТ | C27: 1 | D27: =C27*(1+$C$15) | E27: =D27*(1+$C$15) | F27: =E27*(1+$C$15) | G27: =F27*(1+$C$15) | H27: Год N = Год N-1 × (1 + рост ФОТ)
B28: пользователи | C28: =C7/$C$7 | D28: =D7/$C$7 | E28: =E7/$C$7 | F28: =F7/$C$7 | G28: =G7/$C$7 | H28: Пропорционально числу активных пользователей
B29: заказы | C29: =C8/$C$8 | D29: =D8/$C$8 | E29: =E8/$C$8 | F29: =F8/$C$8 | G29: =G8/$C$8 | H29: Пропорционально числу заказов
B30: GMV | C30: =C10/$C$10 | D30: =D10/$C$10 | E30: =E10/$C$10 | F30: =F10/$C$10 | G30: =G10/$C$10 | H30: Пропорционально обороту
B32: Драйвер «пользователи» — упрощение: облачные расходы редко растут строго линейно (есть эффект масштаба и обратный эффект — рост нагрузки на БД). При желании введи свой драйвер отдельной строкой в таблице индексов.

Sheet TCO-V1
B2: TCO на 5 лет - V1 Модульный монолит на managed-сервисах
B3: Заполняем колонки «Драйвер роста» и «База, $/год (Год 1)». Годы 1–5 считаются автоматически.
B5: Статья затрат | C5: Драйвер роста | D5: База, $/год (Год 1) | E5: Год 1 | F5: Год 2 | G5: Год 3 | H5: Год 4 | I5: Год 5 | J5: Итого 5 лет | K5: Доля | L5: Комментарий / источник
B6: БЛОК 1. Облачная инфраструктура (OpEx)
B7: Compute: ноды / контейнеры / serverless | C7: пользователи | D7: 7200 | E7: =IF($D7="","",$D7*INDEX(Допущения!$C$25:$G$30,MATCH($C7,Допущения!$B$25:$B$30,0),1)) | F7: =IF($D7="","",$D7*INDEX(Допущения!$C$25:$G$30,MATCH($C7,Допущения!$B$25:$B$30,0),2)) | G7: =IF($D7="","",$D7*INDEX(Допущения!$C$25:$G$30,MATCH($C7,Допущения!$B$25:$B$30,0),3)) | H7: =IF($D7="","",$D7*INDEX(Допущения!$C$25:$G$30,MATCH($C7,Допущения!$B$25:$B$30,0),4)) | I7: =IF($D7="","",$D7*INDEX(Допущения!$C$25:$G$30,MATCH($C7,Допущения!$B$25:$B$30,0),5)) | J7: =SUM(E7:I7) | L7: Managed-контейнеры (Cloud Run, ECS Fargate или аналог): 2-4 инстанса Go-монолита + воркеры
B8: Управляемые БД (PostgreSQL, реплики) | C8: пользователи | D8: 6000 | E8: =IF($D8="","",$D8*INDEX(Допущения!$C$25:$G$30,MATCH($C8,Допущения!$B$25:$B$30,0),1)) | F8: =IF($D8="","",$D8*INDEX(Допущения!$C$25:$G$30,MATCH($C8,Допущения!$B$25:$B$30,0),2)) | G8: =IF($D8="","",$D8*INDEX(Допущения!$C$25:$G$30,MATCH($C8,Допущения!$B$25:$B$30,0),3)) | H8: =IF($D8="","",$D8*INDEX(Допущения!$C$25:$G$30,MATCH($C8,Допущения!$B$25:$B$30,0),4)) | I8: =IF($D8="","",$D8*INDEX(Допущения!$C$25:$G$30,MATCH($C8,Допущения!$B$25:$B$30,0),5)) | J8: =SUM(E8:I8) | L8: Managed PostgreSQL HA: primary + standby
B9: Хранилище объектов и резервные копии | C9: пользователи | D9: 1200 | E9: =IF($D9="","",$D9*INDEX(Допущения!$C$25:$G$30,MATCH($C9,Допущения!$B$25:$B$30,0),1)) | F9: =IF($D9="","",$D9*INDEX(Допущения!$C$25:$G$30,MATCH($C9,Допущения!$B$25:$B$30,0),2)) | G9: =IF($D9="","",$D9*INDEX(Допущения!$C$25:$G$30,MATCH($C9,Допущения!$B$25:$B$30,0),3)) | H9: =IF($D9="","",$D9*INDEX(Допущения!$C$25:$G$30,MATCH($C9,Допущения!$B$25:$B$30,0),4)) | I9: =IF($D9="","",$D9*INDEX(Допущения!$C$25:$G$30,MATCH($C9,Допущения!$B$25:$B$30,0),5)) | J9: =SUM(E9:I9) | L9: Объектное хранилище: фото 5000 SKU, бэкапы
B10: CDN и исходящий трафик | C10: пользователи | D10: 4800 | E10: =IF($D10="","",$D10*INDEX(Допущения!$C$25:$G$30,MATCH($C10,Допущения!$B$25:$B$30,0),1)) | F10: =IF($D10="","",$D10*INDEX(Допущения!$C$25:$G$30,MATCH($C10,Допущения!$B$25:$B$30,0),2)) | G10: =IF($D10="","",$D10*INDEX(Допущения!$C$25:$G$30,MATCH($C10,Допущения!$B$25:$B$30,0),3)) | H10: =IF($D10="","",$D10*INDEX(Допущения!$C$25:$G$30,MATCH($C10,Допущения!$B$25:$B$30,0),4)) | I10: =IF($D10="","",$D10*INDEX(Допущения!$C$25:$G$30,MATCH($C10,Допущения!$B$25:$B$30,0),5)) | J10: =SUM(E10:I10) | L10: CDN для фото и статики, WebP, кеш на краю для 3G
B11: Очереди / стриминг (Kafka, SQS) | C11: заказы | D11: 600 | E11: =IF($D11="","",$D11*INDEX(Допущения!$C$25:$G$30,MATCH($C11,Допущения!$B$25:$B$30,0),1)) | F11: =IF($D11="","",$D11*INDEX(Допущения!$C$25:$G$30,MATCH($C11,Допущения!$B$25:$B$30,0),2)) | G11: =IF($D11="","",$D11*INDEX(Допущения!$C$25:$G$30,MATCH($C11,Допущения!$B$25:$B$30,0),3)) | H11: =IF($D11="","",$D11*INDEX(Допущения!$C$25:$G$30,MATCH($C11,Допущения!$B$25:$B$30,0),4)) | I11: =IF($D11="","",$D11*INDEX(Допущения!$C$25:$G$30,MATCH($C11,Допущения!$B$25:$B$30,0),5)) | J11: =SUM(E11:I11) | L11: Managed-очередь (SQS, Pub/Sub) для уведомлений и вебхуков
B12: Резервный регион / DR | C12: пользователи | D12: 3600 | E12: =IF($D12="","",$D12*INDEX(Допущения!$C$25:$G$30,MATCH($C12,Допущения!$B$25:$B$30,0),1)) | F12: =IF($D12="","",$D12*INDEX(Допущения!$C$25:$G$30,MATCH($C12,Допущения!$B$25:$B$30,0),2)) | G12: =IF($D12="","",$D12*INDEX(Допущения!$C$25:$G$30,MATCH($C12,Допущения!$B$25:$B$30,0),3)) | H12: =IF($D12="","",$D12*INDEX(Допущения!$C$25:$G$30,MATCH($C12,Допущения!$B$25:$B$30,0),4)) | I12: =IF($D12="","",$D12*INDEX(Допущения!$C$25:$G$30,MATCH($C12,Допущения!$B$25:$B$30,0),5)) | J12: =SUM(E12:I12) | L12: Warm standby: реплика БД и бэкапы во втором регионе
B13: Локальное размещение данных (NDPR, Нигерия) | C13: инфляция | D13: 8400 | E13: =IF($D13="","",$D13*INDEX(Допущения!$C$25:$G$30,MATCH($C13,Допущения!$B$25:$B$30,0),1)) | F13: =IF($D13="","",$D13*INDEX(Допущения!$C$25:$G$30,MATCH($C13,Допущения!$B$25:$B$30,0),2)) | G13: =IF($D13="","",$D13*INDEX(Допущения!$C$25:$G$30,MATCH($C13,Допущения!$B$25:$B$30,0),3)) | H13: =IF($D13="","",$D13*INDEX(Допущения!$C$25:$G$30,MATCH($C13,Допущения!$B$25:$B$30,0),4)) | I13: =IF($D13="","",$D13*INDEX(Допущения!$C$25:$G$30,MATCH($C13,Допущения!$B$25:$B$30,0),5)) | J13: =SUM(E13:I13) | L13: Локальный провайдер в Нигерии: хранилище ПДн, 2 ВМ + БД
B14: Мультирегион с Год 3 (по триггеру) | C14: фикс | E14: 0 | F14: 0 | G14: 120000 | H14: 160000 | I14: 200000 | J14: =SUM(E14:I14) | L14: Переход на мультирегион с Год 3 по триггеру нагрузки. Числа введены вручную
B15: Итого по блоку | E15: =SUM(E7:E14) | F15: =SUM(F7:F14) | G15: =SUM(G7:G14) | H15: =SUM(H7:H14) | I15: =SUM(I7:I14) | J15: =SUM(J7:J14) | K15: =IFERROR(J15/$J$51,0)
B17: БЛОК 2. Лицензии, SaaS и инструменты
B18: Observability (метрики, логи, трейсинг) | C18: пользователи | D18: 1800 | E18: =IF($D18="","",$D18*INDEX(Допущения!$C$25:$G$30,MATCH($C18,Допущения!$B$25:$B$30,0),1)) | F18: =IF($D18="","",$D18*INDEX(Допущения!$C$25:$G$30,MATCH($C18,Допущения!$B$25:$B$30,0),2)) | G18: =IF($D18="","",$D18*INDEX(Допущения!$C$25:$G$30,MATCH($C18,Допущения!$B$25:$B$30,0),3)) | H18: =IF($D18="","",$D18*INDEX(Допущения!$C$25:$G$30,MATCH($C18,Допущения!$B$25:$B$30,0),4)) | I18: =IF($D18="","",$D18*INDEX(Допущения!$C$25:$G$30,MATCH($C18,Допущения!$B$25:$B$30,0),5)) | J18: =SUM(E18:I18) | L18: Managed Grafana + OpenTelemetry, базовый тариф
B19: CI/CD, репозиторий, артефакты | C19: инфляция | D19: 1200 | E19: =IF($D19="","",$D19*INDEX(Допущения!$C$25:$G$30,MATCH($C19,Допущения!$B$25:$B$30,0),1)) | F19: =IF($D19="","",$D19*INDEX(Допущения!$C$25:$G$30,MATCH($C19,Допущения!$B$25:$B$30,0),2)) | G19: =IF($D19="","",$D19*INDEX(Допущения!$C$25:$G$30,MATCH($C19,Допущения!$B$25:$B$30,0),3)) | H19: =IF($D19="","",$D19*INDEX(Допущения!$C$25:$G$30,MATCH($C19,Допущения!$B$25:$B$30,0),4)) | I19: =IF($D19="","",$D19*INDEX(Допущения!$C$25:$G$30,MATCH($C19,Допущения!$B$25:$B$30,0),5)) | J19: =SUM(E19:I19) | L19: GitHub Team + Actions
B20: Безопасность: WAF, секреты, антифрод | C20: пользователи | D20: 1800 | E20: =IF($D20="","",$D20*INDEX(Допущения!$C$25:$G$30,MATCH($C20,Допущения!$B$25:$B$30,0),1)) | F20: =IF($D20="","",$D20*INDEX(Допущения!$C$25:$G$30,MATCH($C20,Допущения!$B$25:$B$30,0),2)) | G20: =IF($D20="","",$D20*INDEX(Допущения!$C$25:$G$30,MATCH($C20,Допущения!$B$25:$B$30,0),3)) | H20: =IF($D20="","",$D20*INDEX(Допущения!$C$25:$G$30,MATCH($C20,Допущения!$B$25:$B$30,0),4)) | I20: =IF($D20="","",$D20*INDEX(Допущения!$C$25:$G$30,MATCH($C20,Допущения!$B$25:$B$30,0),5)) | J20: =SUM(E20:I20) | L20: WAF, секреты, сертификаты
B21: WhatsApp Business API (подписка) | C21: инфляция | D21: 1200 | E21: =IF($D21="","",$D21*INDEX(Допущения!$C$25:$G$30,MATCH($C21,Допущения!$B$25:$B$30,0),1)) | F21: =IF($D21="","",$D21*INDEX(Допущения!$C$25:$G$30,MATCH($C21,Допущения!$B$25:$B$30,0),2)) | G21: =IF($D21="","",$D21*INDEX(Допущения!$C$25:$G$30,MATCH($C21,Допущения!$B$25:$B$30,0),3)) | H21: =IF($D21="","",$D21*INDEX(Допущения!$C$25:$G$30,MATCH($C21,Допущения!$B$25:$B$30,0),4)) | I21: =IF($D21="","",$D21*INDEX(Допущения!$C$25:$G$30,MATCH($C21,Допущения!$B$25:$B$30,0),5)) | J21: =SUM(E21:I21) | L21: BSP-подписка WhatsApp Business API
B22: Прочее ПО и подписки | C22: инфляция | D22: 1200 | E22: =IF($D22="","",$D22*INDEX(Допущения!$C$25:$G$30,MATCH($C22,Допущения!$B$25:$B$30,0),1)) | F22: =IF($D22="","",$D22*INDEX(Допущения!$C$25:$G$30,MATCH($C22,Допущения!$B$25:$B$30,0),2)) | G22: =IF($D22="","",$D22*INDEX(Допущения!$C$25:$G$30,MATCH($C22,Допущения!$B$25:$B$30,0),3)) | H22: =IF($D22="","",$D22*INDEX(Допущения!$C$25:$G$30,MATCH($C22,Допущения!$B$25:$B$30,0),4)) | I22: =IF($D22="","",$D22*INDEX(Допущения!$C$25:$G$30,MATCH($C22,Допущения!$B$25:$B$30,0),5)) | J22: =SUM(E22:I22) | L22: Трекер, дизайн
C23: фикс | E23: =IF($D23="","",$D23*INDEX(Допущения!$C$25:$G$30,MATCH($C23,Допущения!$B$25:$B$30,0),1)) | F23: =IF($D23="","",$D23*INDEX(Допущения!$C$25:$G$30,MATCH($C23,Допущения!$B$25:$B$30,0),2)) | G23: =IF($D23="","",$D23*INDEX(Допущения!$C$25:$G$30,MATCH($C23,Допущения!$B$25:$B$30,0),3)) | H23: =IF($D23="","",$D23*INDEX(Допущения!$C$25:$G$30,MATCH($C23,Допущения!$B$25:$B$30,0),4)) | I23: =IF($D23="","",$D23*INDEX(Допущения!$C$25:$G$30,MATCH($C23,Допущения!$B$25:$B$30,0),5)) | J23: =SUM(E23:I23) | L23: Своя статья
B24: Итого по блоку | E24: =SUM(E18:E23) | F24: =SUM(F18:F23) | G24: =SUM(G18:G23) | H24: =SUM(H18:H23) | I24: =SUM(I18:I23) | J24: =SUM(J18:J23) | K24: =IFERROR(J24/$J$51,0)
B26: БЛОК 3. Транзакционные расходы (Buy / Partner)
B27: Комиссии платёжных провайдеров | C27: GMV | D27: 480000 | E27: =IF($D27="","",$D27*INDEX(Допущения!$C$25:$G$30,MATCH($C27,Допущения!$B$25:$B$30,0),1)) | F27: =IF($D27="","",$D27*INDEX(Допущения!$C$25:$G$30,MATCH($C27,Допущения!$B$25:$B$30,0),2)) | G27: =IF($D27="","",$D27*INDEX(Допущения!$C$25:$G$30,MATCH($C27,Допущения!$B$25:$B$30,0),3)) | H27: =IF($D27="","",$D27*INDEX(Допущения!$C$25:$G$30,MATCH($C27,Допущения!$B$25:$B$30,0),4)) | I27: =IF($D27="","",$D27*INDEX(Допущения!$C$25:$G$30,MATCH($C27,Допущения!$B$25:$B$30,0),5)) | J27: =SUM(E27:I27) | L27: 2,0% GMV all-in: M-Pesa Daraja (KE), Flutterwave и Paystack (NG). Лимит CFO 2,5% (А6). Одинаково для всех вариантов
B28: SMS-уведомления | C28: заказы | D28: 90000 | E28: =IF($D28="","",$D28*INDEX(Допущения!$C$25:$G$30,MATCH($C28,Допущения!$B$25:$B$30,0),1)) | F28: =IF($D28="","",$D28*INDEX(Допущения!$C$25:$G$30,MATCH($C28,Допущения!$B$25:$B$30,0),2)) | G28: =IF($D28="","",$D28*INDEX(Допущения!$C$25:$G$30,MATCH($C28,Допущения!$B$25:$B$30,0),3)) | H28: =IF($D28="","",$D28*INDEX(Допущения!$C$25:$G$30,MATCH($C28,Допущения!$B$25:$B$30,0),4)) | I28: =IF($D28="","",$D28*INDEX(Допущения!$C$25:$G$30,MATCH($C28,Допущения!$B$25:$B$30,0),5)) | J28: =SUM(E28:I28) | L28: 3 SMS на заказ × $0,025
B29: WhatsApp-сообщения (за диалог) | C29: заказы | D29: 18000 | E29: =IF($D29="","",$D29*INDEX(Допущения!$C$25:$G$30,MATCH($C29,Допущения!$B$25:$B$30,0),1)) | F29: =IF($D29="","",$D29*INDEX(Допущения!$C$25:$G$30,MATCH($C29,Допущения!$B$25:$B$30,0),2)) | G29: =IF($D29="","",$D29*INDEX(Допущения!$C$25:$G$30,MATCH($C29,Допущения!$B$25:$B$30,0),3)) | H29: =IF($D29="","",$D29*INDEX(Допущения!$C$25:$G$30,MATCH($C29,Допущения!$B$25:$B$30,0),4)) | I29: =IF($D29="","",$D29*INDEX(Допущения!$C$25:$G$30,MATCH($C29,Допущения!$B$25:$B$30,0),5)) | J29: =SUM(E29:I29) | L29: 1 utility-диалог WhatsApp на заказ × $0,015
B30: Логистика: интеграции и комиссии партнёров | C30: заказы | D30: 180000 | E30: =IF($D30="","",$D30*INDEX(Допущения!$C$25:$G$30,MATCH($C30,Допущения!$B$25:$B$30,0),1)) | F30: =IF($D30="","",$D30*INDEX(Допущения!$C$25:$G$30,MATCH($C30,Допущения!$B$25:$B$30,0),2)) | G30: =IF($D30="","",$D30*INDEX(Допущения!$C$25:$G$30,MATCH($C30,Допущения!$B$25:$B$30,0),3)) | H30: =IF($D30="","",$D30*INDEX(Допущения!$C$25:$G$30,MATCH($C30,Допущения!$B$25:$B$30,0),4)) | I30: =IF($D30="","",$D30*INDEX(Допущения!$C$25:$G$30,MATCH($C30,Допущения!$B$25:$B$30,0),5)) | J30: =SUM(E30:I30) | L30: Сбор API Sendbox и Sendy $0,15 на заказ. Тариф доставки платит покупатель
C31: фикс | E31: =IF($D31="","",$D31*INDEX(Допущения!$C$25:$G$30,MATCH($C31,Допущения!$B$25:$B$30,0),1)) | F31: =IF($D31="","",$D31*INDEX(Допущения!$C$25:$G$30,MATCH($C31,Допущения!$B$25:$B$30,0),2)) | G31: =IF($D31="","",$D31*INDEX(Допущения!$C$25:$G$30,MATCH($C31,Допущения!$B$25:$B$30,0),3)) | H31: =IF($D31="","",$D31*INDEX(Допущения!$C$25:$G$30,MATCH($C31,Допущения!$B$25:$B$30,0),4)) | I31: =IF($D31="","",$D31*INDEX(Допущения!$C$25:$G$30,MATCH($C31,Допущения!$B$25:$B$30,0),5)) | J31: =SUM(E31:I31) | L31: Своя статья
B32: Итого по блоку | E32: =SUM(E27:E31) | F32: =SUM(F27:F31) | G32: =SUM(G27:G31) | H32: =SUM(H27:H31) | I32: =SUM(I27:I31) | J32: =SUM(J27:J31) | K32: =IFERROR(J32/$J$51,0)
B34: БЛОК 4. Команда (ФОТ)
B35: Разработка (FTE × годовая ставка) | C35: ФОТ | D35: 300000 | E35: =IF($D35="","",$D35*INDEX(Допущения!$C$25:$G$30,MATCH($C35,Допущения!$B$25:$B$30,0),1)) | F35: =IF($D35="","",$D35*INDEX(Допущения!$C$25:$G$30,MATCH($C35,Допущения!$B$25:$B$30,0),2)) | G35: =IF($D35="","",$D35*INDEX(Допущения!$C$25:$G$30,MATCH($C35,Допущения!$B$25:$B$30,0),3)) | H35: =IF($D35="","",$D35*INDEX(Допущения!$C$25:$G$30,MATCH($C35,Допущения!$B$25:$B$30,0),4)) | I35: =IF($D35="","",$D35*INDEX(Допущения!$C$25:$G$30,MATCH($C35,Допущения!$B$25:$B$30,0),5)) | J35: =SUM(E35:I35) | L35: 5 контракторов × $60k
B36: DevOps / SRE | C36: ФОТ | D36: 60000 | E36: =IF($D36="","",$D36*INDEX(Допущения!$C$25:$G$30,MATCH($C36,Допущения!$B$25:$B$30,0),1)) | F36: =IF($D36="","",$D36*INDEX(Допущения!$C$25:$G$30,MATCH($C36,Допущения!$B$25:$B$30,0),2)) | G36: =IF($D36="","",$D36*INDEX(Допущения!$C$25:$G$30,MATCH($C36,Допущения!$B$25:$B$30,0),3)) | H36: =IF($D36="","",$D36*INDEX(Допущения!$C$25:$G$30,MATCH($C36,Допущения!$B$25:$B$30,0),4)) | I36: =IF($D36="","",$D36*INDEX(Допущения!$C$25:$G$30,MATCH($C36,Допущения!$B$25:$B$30,0),5)) | J36: =SUM(E36:I36) | L36: 1 DevOps: БД и очереди эксплуатирует провайдер
B37: Поддержка и дежурства 24/7 | C37: ФОТ | D37: 24000 | E37: =IF($D37="","",$D37*INDEX(Допущения!$C$25:$G$30,MATCH($C37,Допущения!$B$25:$B$30,0),1)) | F37: =IF($D37="","",$D37*INDEX(Допущения!$C$25:$G$30,MATCH($C37,Допущения!$B$25:$B$30,0),2)) | G37: =IF($D37="","",$D37*INDEX(Допущения!$C$25:$G$30,MATCH($C37,Допущения!$B$25:$B$30,0),3)) | H37: =IF($D37="","",$D37*INDEX(Допущения!$C$25:$G$30,MATCH($C37,Допущения!$B$25:$B$30,0),4)) | I37: =IF($D37="","",$D37*INDEX(Допущения!$C$25:$G$30,MATCH($C37,Допущения!$B$25:$B$30,0),5)) | J37: =SUM(E37:I37) | L37: Надбавка за ротацию дежурств внутри 6 контракторов
B38: Архитектура и менеджмент | C38: ФОТ | D38: 150000 | E38: =IF($D38="","",$D38*INDEX(Допущения!$C$25:$G$30,MATCH($C38,Допущения!$B$25:$B$30,0),1)) | F38: =IF($D38="","",$D38*INDEX(Допущения!$C$25:$G$30,MATCH($C38,Допущения!$B$25:$B$30,0),2)) | G38: =IF($D38="","",$D38*INDEX(Допущения!$C$25:$G$30,MATCH($C38,Допущения!$B$25:$B$30,0),3)) | H38: =IF($D38="","",$D38*INDEX(Допущения!$C$25:$G$30,MATCH($C38,Допущения!$B$25:$B$30,0),4)) | I38: =IF($D38="","",$D38*INDEX(Допущения!$C$25:$G$30,MATCH($C38,Допущения!$B$25:$B$30,0),5)) | J38: =SUM(E38:I38) | L38: CTO и SA, доля на платформу. Одинаково во всех вариантах
B39: Усиление SRE с Год 3 | C39: фикс | E39: 0 | F39: 0 | G39: 120000 | H39: 132000 | I39: 145000 | J39: =SUM(E39:I39) | L39: +2 SRE при переходе на мультирегион. Числа введены вручную
B40: Итого по блоку | E40: =SUM(E35:E39) | F40: =SUM(F35:F39) | G40: =SUM(G35:G39) | H40: =SUM(H35:H39) | I40: =SUM(I35:I39) | J40: =SUM(J35:J39) | K40: =IFERROR(J40/$J$51,0)
B42: БЛОК 5. Разовые затраты и комплаенс
B43: Юридический и комплаенс-аудит (NDPR, POPIA, KICA) | C43: фикс | D43: 25000 | E43: =IF($D43="","",$D43*INDEX(Допущения!$C$25:$G$30,MATCH($C43,Допущения!$B$25:$B$30,0),1)) | F43: 10000 | G43: 10000 | H43: 10000 | I43: 10000 | J43: =SUM(E43:I43) | L43: Регистрация NDPC, DPO, аудит. Далее ежегодный аудит NDPR $10k (А3)
B44: Пентест и аудит безопасности | C44: инфляция | D44: 10000 | E44: =IF($D44="","",$D44*INDEX(Допущения!$C$25:$G$30,MATCH($C44,Допущения!$B$25:$B$30,0),1)) | F44: =IF($D44="","",$D44*INDEX(Допущения!$C$25:$G$30,MATCH($C44,Допущения!$B$25:$B$30,0),2)) | G44: =IF($D44="","",$D44*INDEX(Допущения!$C$25:$G$30,MATCH($C44,Допущения!$B$25:$B$30,0),3)) | H44: =IF($D44="","",$D44*INDEX(Допущения!$C$25:$G$30,MATCH($C44,Допущения!$B$25:$B$30,0),4)) | I44: =IF($D44="","",$D44*INDEX(Допущения!$C$25:$G$30,MATCH($C44,Допущения!$B$25:$B$30,0),5)) | J44: =SUM(E44:I44) | L44: Ежегодный пентест
B45: Миграция данных и интеграции при запуске | C45: фикс | D45: 0 | E45: =IF($D45="","",$D45*INDEX(Допущения!$C$25:$G$30,MATCH($C45,Допущения!$B$25:$B$30,0),1)) | F45: =IF($D45="","",$D45*INDEX(Допущения!$C$25:$G$30,MATCH($C45,Допущения!$B$25:$B$30,0),2)) | G45: =IF($D45="","",$D45*INDEX(Допущения!$C$25:$G$30,MATCH($C45,Допущения!$B$25:$B$30,0),3)) | H45: =IF($D45="","",$D45*INDEX(Допущения!$C$25:$G$30,MATCH($C45,Допущения!$B$25:$B$30,0),4)) | I45: =IF($D45="","",$D45*INDEX(Допущения!$C$25:$G$30,MATCH($C45,Допущения!$B$25:$B$30,0),5)) | J45: =SUM(E45:I45) | L45: Greenfield, миграции нет
B46: Обучение команды и найм | C46: фикс | D46: 0 | E46: =IF($D46="","",$D46*INDEX(Допущения!$C$25:$G$30,MATCH($C46,Допущения!$B$25:$B$30,0),1)) | F46: =IF($D46="","",$D46*INDEX(Допущения!$C$25:$G$30,MATCH($C46,Допущения!$B$25:$B$30,0),2)) | G46: =IF($D46="","",$D46*INDEX(Допущения!$C$25:$G$30,MATCH($C46,Допущения!$B$25:$B$30,0),3)) | H46: =IF($D46="","",$D46*INDEX(Допущения!$C$25:$G$30,MATCH($C46,Допущения!$B$25:$B$30,0),4)) | I46: =IF($D46="","",$D46*INDEX(Допущения!$C$25:$G$30,MATCH($C46,Допущения!$B$25:$B$30,0),5)) | J46: =SUM(E46:I46) | L46: Найм заморожен до декабря (А6)
...

Sheet TCO-V2
B2: TCO на 5 лет - V2 Сервисная архитектура, 6-8 сервисов на managed Kubernetes
B3: Заполняем колонки «Драйвер роста» и «База, $/год (Год 1)». Годы 1–5 считаются автоматически.
B5: Статья затрат | C5: Драйвер роста | D5: База, $/год (Год 1) | E5: Год 1 | F5: Год 2 | G5: Год 3 | H5: Год 4 | I5: Год 5 | J5: Итого 5 лет | K5: Доля | L5: Комментарий / источник
B6: БЛОК 1. Облачная инфраструктура (OpEx)
B7: Compute: ноды / контейнеры / serverless | C7: пользователи | D7: 21600 | E7: =IF($D7="","",$D7*INDEX(Допущения!$C$25:$G$30,MATCH($C7,Допущения!$B$25:$B$30,0),1)) | F7: =IF($D7="","",$D7*INDEX(Допущения!$C$25:$G$30,MATCH($C7,Допущения!$B$25:$B$30,0),2)) | G7: =IF($D7="","",$D7*INDEX(Допущения!$C$25:$G$30,MATCH($C7,Допущения!$B$25:$B$30,0),3)) | H7: =IF($D7="","",$D7*INDEX(Допущения!$C$25:$G$30,MATCH($C7,Допущения!$B$25:$B$30,0),4)) | I7: =IF($D7="","",$D7*INDEX(Допущения!$C$25:$G$30,MATCH($C7,Допущения!$B$25:$B$30,0),5)) | J7: =SUM(E7:I7) | L7: Managed Kubernetes, 1 кластер, 6-8 нод
B8: Управляемые БД (PostgreSQL, реплики) | C8: пользователи | D8: 14400 | E8: =IF($D8="","",$D8*INDEX(Допущения!$C$25:$G$30,MATCH($C8,Допущения!$B$25:$B$30,0),1)) | F8: =IF($D8="","",$D8*INDEX(Допущения!$C$25:$G$30,MATCH($C8,Допущения!$B$25:$B$30,0),2)) | G8: =IF($D8="","",$D8*INDEX(Допущения!$C$25:$G$30,MATCH($C8,Допущения!$B$25:$B$30,0),3)) | H8: =IF($D8="","",$D8*INDEX(Допущения!$C$25:$G$30,MATCH($C8,Допущения!$B$25:$B$30,0),4)) | I8: =IF($D8="","",$D8*INDEX(Допущения!$C$25:$G$30,MATCH($C8,Допущения!$B$25:$B$30,0),5)) | J8: =SUM(E8:I8) | L8: 3 managed PostgreSQL HA, БД на группу сервисов
B9: Хранилище объектов и резервные копии | C9: пользователи | D9: 1200 | E9: =IF($D9="","",$D9*INDEX(Допущения!$C$25:$G$30,MATCH($C9,Допущения!$B$25:$B$30,0),1)) | F9: =IF($D9="","",$D9*INDEX(Допущения!$C$25:$G$30,MATCH($C9,Допущения!$B$25:$B$30,0),2)) | G9: =IF($D9="","",$D9*INDEX(Допущения!$C$25:$G$30,MATCH($C9,Допущения!$B$25:$B$30,0),3)) | H9: =IF($D9="","",$D9*INDEX(Допущения!$C$25:$G$30,MATCH($C9,Допущения!$B$25:$B$30,0),4)) | I9: =IF($D9="","",$D9*INDEX(Допущения!$C$25:$G$30,MATCH($C9,Допущения!$B$25:$B$30,0),5)) | J9: =SUM(E9:I9) | L9: Объектное хранилище: фото, бэкапы
B10: CDN и исходящий трафик | C10: пользователи | D10: 4800 | E10: =IF($D10="","",$D10*INDEX(Допущения!$C$25:$G$30,MATCH($C10,Допущения!$B$25:$B$30,0),1)) | F10: =IF($D10="","",$D10*INDEX(Допущения!$C$25:$G$30,MATCH($C10,Допущения!$B$25:$B$30,0),2)) | G10: =IF($D10="","",$D10*INDEX(Допущения!$C$25:$G$30,MATCH($C10,Допущения!$B$25:$B$30,0),3)) | H10: =IF($D10="","",$D10*INDEX(Допущения!$C$25:$G$30,MATCH($C10,Допущения!$B$25:$B$30,0),4)) | I10: =IF($D10="","",$D10*INDEX(Допущения!$C$25:$G$30,MATCH($C10,Допущения!$B$25:$B$30,0),5)) | J10: =SUM(E10:I10) | L10: CDN для фото и статики
B11: Очереди / стриминг (Kafka, SQS) | C11: заказы | D11: 7200 | E11: =IF($D11="","",$D11*INDEX(Допущения!$C$25:$G$30,MATCH($C11,Допущения!$B$25:$B$30,0),1)) | F11: =IF($D11="","",$D11*INDEX(Допущения!$C$25:$G$30,MATCH($C11,Допущения!$B$25:$B$30,0),2)) | G11: =IF($D11="","",$D11*INDEX(Допущения!$C$25:$G$30,MATCH($C11,Допущения!$B$25:$B$30,0),3)) | H11: =IF($D11="","",$D11*INDEX(Допущения!$C$25:$G$30,MATCH($C11,Допущения!$B$25:$B$30,0),4)) | I11: =IF($D11="","",$D11*INDEX(Допущения!$C$25:$G$30,MATCH($C11,Допущения!$B$25:$B$30,0),5)) | J11: =SUM(E11:I11) | L11: Managed Kafka, минимальный тариф
B12: Резервный регион / DR | C12: пользователи | D12: 9600 | E12: =IF($D12="","",$D12*INDEX(Допущения!$C$25:$G$30,MATCH($C12,Допущения!$B$25:$B$30,0),1)) | F12: =IF($D12="","",$D12*INDEX(Допущения!$C$25:$G$30,MATCH($C12,Допущения!$B$25:$B$30,0),2)) | G12: =IF($D12="","",$D12*INDEX(Допущения!$C$25:$G$30,MATCH($C12,Допущения!$B$25:$B$30,0),3)) | H12: =IF($D12="","",$D12*INDEX(Допущения!$C$25:$G$30,MATCH($C12,Допущения!$B$25:$B$30,0),4)) | I12: =IF($D12="","",$D12*INDEX(Допущения!$C$25:$G$30,MATCH($C12,Допущения!$B$25:$B$30,0),5)) | J12: =SUM(E12:I12) | L12: Warm standby кластера во втором регионе
B13: Локальное размещение данных (NDPR, Нигерия) | C13: инфляция | D13: 12000 | E13: =IF($D13="","",$D13*INDEX(Допущения!$C$25:$G$30,MATCH($C13,Допущения!$B$25:$B$30,0),1)) | F13: =IF($D13="","",$D13*INDEX(Допущения!$C$25:$G$30,MATCH($C13,Допущения!$B$25:$B$30,0),2)) | G13: =IF($D13="","",$D13*INDEX(Допущения!$C$25:$G$30,MATCH($C13,Допущения!$B$25:$B$30,0),3)) | H13: =IF($D13="","",$D13*INDEX(Допущения!$C$25:$G$30,MATCH($C13,Допущения!$B$25:$B$30,0),4)) | I13: =IF($D13="","",$D13*INDEX(Допущения!$C$25:$G$30,MATCH($C13,Допущения!$B$25:$B$30,0),5)) | J13: =SUM(E13:I13) | L13: Нода кластера и хранилище ПДн в Нигерии
B14: Мультирегион с Год 3 | C14: фикс | E14: 0 | F14: 0 | G14: 150000 | H14: 200000 | I14: 250000 | J14: =SUM(E14:I14) | L14: Переход на мультирегион с Год 3. Числа введены вручную
B15: Итого по блоку | E15: =SUM(E7:E14) | F15: =SUM(F7:F14) | G15: =SUM(G7:G14) | H15: =SUM(H7:H14) | I15: =SUM(I7:I14) | J15: =SUM(J7:J14) | K15: =IFERROR(J15/$J$51,0)
B17: БЛОК 2. Лицензии, SaaS и инструменты
B18: Observability (метрики, логи, трейсинг) | C18: пользователи | D18: 6000 | E18: =IF($D18="","",$D18*INDEX(Допущения!$C$25:$G$30,MATCH($C18,Допущения!$B$25:$B$30,0),1)) | F18: =IF($D18="","",$D18*INDEX(Допущения!$C$25:$G$30,MATCH($C18,Допущения!$B$25:$B$30,0),2)) | G18: =IF($D18="","",$D18*INDEX(Допущения!$C$25:$G$30,MATCH($C18,Допущения!$B$25:$B$30,0),3)) | H18: =IF($D18="","",$D18*INDEX(Допущения!$C$25:$G$30,MATCH($C18,Допущения!$B$25:$B$30,0),4)) | I18: =IF($D18="","",$D18*INDEX(Допущения!$C$25:$G$30,MATCH($C18,Допущения!$B$25:$B$30,0),5)) | J18: =SUM(E18:I18) | L18: Managed observability: метрики, логи, трейсы по 6-8 сервисам
B19: CI/CD, репозиторий, артефакты | C19: инфляция | D19: 2400 | E19: =IF($D19="","",$D19*INDEX(Допущения!$C$25:$G$30,MATCH($C19,Допущения!$B$25:$B$30,0),1)) | F19: =IF($D19="","",$D19*INDEX(Допущения!$C$25:$G$30,MATCH($C19,Допущения!$B$25:$B$30,0),2)) | G19: =IF($D19="","",$D19*INDEX(Допущения!$C$25:$G$30,MATCH($C19,Допущения!$B$25:$B$30,0),3)) | H19: =IF($D19="","",$D19*INDEX(Допущения!$C$25:$G$30,MATCH($C19,Допущения!$B$25:$B$30,0),4)) | I19: =IF($D19="","",$D19*INDEX(Допущения!$C$25:$G$30,MATCH($C19,Допущения!$B$25:$B$30,0),5)) | J19: =SUM(E19:I19) | L19: GitHub Team + Actions, реестр образов
B20: Безопасность: WAF, секреты, антифрод | C20: пользователи | D20: 3600 | E20: =IF($D20="","",$D20*INDEX(Допущения!$C$25:$G$30,MATCH($C20,Допущения!$B$25:$B$30,0),1)) | F20: =IF($D20="","",$D20*INDEX(Допущения!$C$25:$G$30,MATCH($C20,Допущения!$B$25:$B$30,0),2)) | G20: =IF($D20="","",$D20*INDEX(Допущения!$C$25:$G$30,MATCH($C20,Допущения!$B$25:$B$30,0),3)) | H20: =IF($D20="","",$D20*INDEX(Допущения!$C$25:$G$30,MATCH($C20,Допущения!$B$25:$B$30,0),4)) | I20: =IF($D20="","",$D20*INDEX(Допущения!$C$25:$G$30,MATCH($C20,Допущения!$B$25:$B$30,0),5)) | J20: =SUM(E20:I20) | L20: WAF, секреты, политики кластера
B21: WhatsApp Business API (подписка) | C21: инфляция | D21: 1200 | E21: =IF($D21="","",$D21*INDEX(Допущения!$C$25:$G$30,MATCH($C21,Допущения!$B$25:$B$30,0),1)) | F21: =IF($D21="","",$D21*INDEX(Допущения!$C$25:$G$30,MATCH($C21,Допущения!$B$25:$B$30,0),2)) | G21: =IF($D21="","",$D21*INDEX(Допущения!$C$25:$G$30,MATCH($C21,Допущения!$B$25:$B$30,0),3)) | H21: =IF($D21="","",$D21*INDEX(Допущения!$C$25:$G$30,MATCH($C21,Допущения!$B$25:$B$30,0),4)) | I21: =IF($D21="","",$D21*INDEX(Допущения!$C$25:$G$30,MATCH($C21,Допущения!$B$25:$B$30,0),5)) | J21: =SUM(E21:I21) | L21: BSP-подписка WhatsApp Business API
B22: Прочее ПО и подписки | C22: инфляция | D22: 1800 | E22: =IF($D22="","",$D22*INDEX(Допущения!$C$25:$G$30,MATCH($C22,Допущения!$B$25:$B$30,0),1)) | F22: =IF($D22="","",$D22*INDEX(Допущения!$C$25:$G$30,MATCH($C22,Допущения!$B$25:$B$30,0),2)) | G22: =IF($D22="","",$D22*INDEX(Допущения!$C$25:$G$30,MATCH($C22,Допущения!$B$25:$B$30,0),3)) | H22: =IF($D22="","",$D22*INDEX(Допущения!$C$25:$G$30,MATCH($C22,Допущения!$B$25:$B$30,0),4)) | I22: =IF($D22="","",$D22*INDEX(Допущения!$C$25:$G$30,MATCH($C22,Допущения!$B$25:$B$30,0),5)) | J22: =SUM(E22:I22) | L22: Трекер, дизайн
C23: фикс | E23: =IF($D23="","",$D23*INDEX(Допущения!$C$25:$G$30,MATCH($C23,Допущения!$B$25:$B$30,0),1)) | F23: =IF($D23="","",$D23*INDEX(Допущения!$C$25:$G$30,MATCH($C23,Допущения!$B$25:$B$30,0),2)) | G23: =IF($D23="","",$D23*INDEX(Допущения!$C$25:$G$30,MATCH($C23,Допущения!$B$25:$B$30,0),3)) | H23: =IF($D23="","",$D23*INDEX(Допущения!$C$25:$G$30,MATCH($C23,Допущения!$B$25:$B$30,0),4)) | I23: =IF($D23="","",$D23*INDEX(Допущения!$C$25:$G$30,MATCH($C23,Допущения!$B$25:$B$30,0),5)) | J23: =SUM(E23:I23) | L23: Своя статья
B24: Итого по блоку | E24: =SUM(E18:E23) | F24: =SUM(F18:F23) | G24: =SUM(G18:G23) | H24: =SUM(H18:H23) | I24: =SUM(I18:I23) | J24: =SUM(J18:J23) | K24: =IFERROR(J24/$J$51,0)
B26: БЛОК 3. Транзакционные расходы (Buy / Partner)
B27: Комиссии платёжных провайдеров | C27: GMV | D27: 480000 | E27: =IF($D27="","",$D27*INDEX(Допущения!$C$25:$G$30,MATCH($C27,Допущения!$B$25:$B$30,0),1)) | F27: =IF($D27="","",$D27*INDEX(Допущения!$C$25:$G$30,MATCH($C27,Допущения!$B$25:$B$30,0),2)) | G27: =IF($D27="","",$D27*INDEX(Допущения!$C$25:$G$30,MATCH($C27,Допущения!$B$25:$B$30,0),3)) | H27: =IF($D27="","",$D27*INDEX(Допущения!$C$25:$G$30,MATCH($C27,Допущения!$B$25:$B$30,0),4)) | I27: =IF($D27="","",$D27*INDEX(Допущения!$C$25:$G$30,MATCH($C27,Допущения!$B$25:$B$30,0),5)) | J27: =SUM(E27:I27) | L27: 2,0% GMV all-in: M-Pesa Daraja (KE), Flutterwave и Paystack (NG). Лимит CFO 2,5% (А6). Одинаково для всех вариантов
B28: SMS-уведомления | C28: заказы | D28: 90000 | E28: =IF($D28="","",$D28*INDEX(Допущения!$C$25:$G$30,MATCH($C28,Допущения!$B$25:$B$30,0),1)) | F28: =IF($D28="","",$D28*INDEX(Допущения!$C$25:$G$30,MATCH($C28,Допущения!$B$25:$B$30,0),2)) | G28: =IF($D28="","",$D28*INDEX(Допущения!$C$25:$G$30,MATCH($C28,Допущения!$B$25:$B$30,0),3)) | H28: =IF($D28="","",$D28*INDEX(Допущения!$C$25:$G$30,MATCH($C28,Допущения!$B$25:$B$30,0),4)) | I28: =IF($D28="","",$D28*INDEX(Допущения!$C$25:$G$30,MATCH($C28,Допущения!$B$25:$B$30,0),5)) | J28: =SUM(E28:I28) | L28: 3 SMS на заказ × $0,025
B29: WhatsApp-сообщения (за диалог) | C29: заказы | D29: 18000 | E29: =IF($D29="","",$D29*INDEX(Допущения!$C$25:$G$30,MATCH($C29,Допущения!$B$25:$B$30,0),1)) | F29: =IF($D29="","",$D29*INDEX(Допущения!$C$25:$G$30,MATCH($C29,Допущения!$B$25:$B$30,0),2)) | G29: =IF($D29="","",$D29*INDEX(Допущения!$C$25:$G$30,MATCH($C29,Допущения!$B$25:$B$30,0),3)) | H29: =IF($D29="","",$D29*INDEX(Допущения!$C$25:$G$30,MATCH($C29,Допущения!$B$25:$B$30,0),4)) | I29: =IF($D29="","",$D29*INDEX(Допущения!$C$25:$G$30,MATCH($C29,Допущения!$B$25:$B$30,0),5)) | J29: =SUM(E29:I29) | L29: 1 utility-диалог WhatsApp на заказ × $0,015
B30: Логистика: интеграции и комиссии партнёров | C30: заказы | D30: 180000 | E30: =IF($D30="","",$D30*INDEX(Допущения!$C$25:$G$30,MATCH($C30,Допущения!$B$25:$B$30,0),1)) | F30: =IF($D30="","",$D30*INDEX(Допущения!$C$25:$G$30,MATCH($C30,Допущения!$B$25:$B$30,0),2)) | G30: =IF($D30="","",$D30*INDEX(Допущения!$C$25:$G$30,MATCH($C30,Допущения!$B$25:$B$30,0),3)) | H30: =IF($D30="","",$D30*INDEX(Допущения!$C$25:$G$30,MATCH($C30,Допущения!$B$25:$B$30,0),4)) | I30: =IF($D30="","",$D30*INDEX(Допущения!$C$25:$G$30,MATCH($C30,Допущения!$B$25:$B$30,0),5)) | J30: =SUM(E30:I30) | L30: Сбор API Sendbox и Sendy $0,15 на заказ. Тариф доставки платит покупатель
C31: фикс | E31: =IF($D31="","",$D31*INDEX(Допущения!$C$25:$G$30,MATCH($C31,Допущения!$B$25:$B$30,0),1)) | F31: =IF($D31="","",$D31*INDEX(Допущения!$C$25:$G$30,MATCH($C31,Допущения!$B$25:$B$30,0),2)) | G31: =IF($D31="","",$D31*INDEX(Допущения!$C$25:$G$30,MATCH($C31,Допущения!$B$25:$B$30,0),3)) | H31: =IF($D31="","",$D31*INDEX(Допущения!$C$25:$G$30,MATCH($C31,Допущения!$B$25:$B$30,0),4)) | I31: =IF($D31="","",$D31*INDEX(Допущения!$C$25:$G$30,MATCH($C31,Допущения!$B$25:$B$30,0),5)) | J31: =SUM(E31:I31) | L31: Своя статья
B32: Итого по блоку | E32: =SUM(E27:E31) | F32: =SUM(F27:F31) | G32: =SUM(G27:G31) | H32: =SUM(H27:H31) | I32: =SUM(I27:I31) | J32: =SUM(J27:J31) | K32: =IFERROR(J32/$J$51,0)
B34: БЛОК 4. Команда (ФОТ)
B35: Разработка (FTE × годовая ставка) | C35: ФОТ | D35: 420000 | E35: =IF($D35="","",$D35*INDEX(Допущения!$C$25:$G$30,MATCH($C35,Допущения!$B$25:$B$30,0),1)) | F35: =IF($D35="","",$D35*INDEX(Допущения!$C$25:$G$30,MATCH($C35,Допущения!$B$25:$B$30,0),2)) | G35: =IF($D35="","",$D35*INDEX(Допущения!$C$25:$G$30,MATCH($C35,Допущения!$B$25:$B$30,0),3)) | H35: =IF($D35="","",$D35*INDEX(Допущения!$C$25:$G$30,MATCH($C35,Допущения!$B$25:$B$30,0),4)) | I35: =IF($D35="","",$D35*INDEX(Допущения!$C$25:$G$30,MATCH($C35,Допущения!$B$25:$B$30,0),5)) | J35: =SUM(E35:I35) | L35: 7 разработчиков × $60k
B36: DevOps / SRE | C36: ФОТ | D36: 120000 | E36: =IF($D36="","",$D36*INDEX(Допущения!$C$25:$G$30,MATCH($C36,Допущения!$B$25:$B$30,0),1)) | F36: =IF($D36="","",$D36*INDEX(Допущения!$C$25:$G$30,MATCH($C36,Допущения!$B$25:$B$30,0),2)) | G36: =IF($D36="","",$D36*INDEX(Допущения!$C$25:$G$30,MATCH($C36,Допущения!$B$25:$B$30,0),3)) | H36: =IF($D36="","",$D36*INDEX(Допущения!$C$25:$G$30,MATCH($C36,Допущения!$B$25:$B$30,0),4)) | I36: =IF($D36="","",$D36*INDEX(Допущения!$C$25:$G$30,MATCH($C36,Допущения!$B$25:$B$30,0),5)) | J36: =SUM(E36:I36) | L36: 2 SRE: кластер, Kafka, сеть
B37: Поддержка и дежурства 24/7 | C37: ФОТ | D37: 48000 | E37: =IF($D37="","",$D37*INDEX(Допущения!$C$25:$G$30,MATCH($C37,Допущения!$B$25:$B$30,0),1)) | F37: =IF($D37="","",$D37*INDEX(Допущения!$C$25:$G$30,MATCH($C37,Допущения!$B$25:$B$30,0),2)) | G37: =IF($D37="","",$D37*INDEX(Допущения!$C$25:$G$30,MATCH($C37,Допущения!$B$25:$B$30,0),3)) | H37: =IF($D37="","",$D37*INDEX(Допущения!$C$25:$G$30,MATCH($C37,Допущения!$B$25:$B$30,0),4)) | I37: =IF($D37="","",$D37*INDEX(Допущения!$C$25:$G$30,MATCH($C37,Допущения!$B$25:$B$30,0),5)) | J37: =SUM(E37:I37) | L37: Ротация дежурств 24/7
B38: Архитектура и менеджмент | C38: ФОТ | D38: 150000 | E38: =IF($D38="","",$D38*INDEX(Допущения!$C$25:$G$30,MATCH($C38,Допущения!$B$25:$B$30,0),1)) | F38: =IF($D38="","",$D38*INDEX(Допущения!$C$25:$G$30,MATCH($C38,Допущения!$B$25:$B$30,0),2)) | G38: =IF($D38="","",$D38*INDEX(Допущения!$C$25:$G$30,MATCH($C38,Допущения!$B$25:$B$30,0),3)) | H38: =IF($D38="","",$D38*INDEX(Допущения!$C$25:$G$30,MATCH($C38,Допущения!$B$25:$B$30,0),4)) | I38: =IF($D38="","",$D38*INDEX(Допущения!$C$25:$G$30,MATCH($C38,Допущения!$B$25:$B$30,0),5)) | J38: =SUM(E38:I38) | L38: CTO и SA, доля на платформу
B39: Усиление SRE с Год 3 | C39: фикс | E39: 0 | F39: 0 | G39: 60000 | H39: 66000 | I39: 72600 | J39: =SUM(E39:I39) | L39: +1 SRE при мультирегионе. Числа введены вручную
B40: Итого по блоку | E40: =SUM(E35:E39) | F40: =SUM(F35:F39) | G40: =SUM(G35:G39) | H40: =SUM(H35:H39) | I40: =SUM(I35:I39) | J40: =SUM(J35:J39) | K40: =IFERROR(J40/$J$51,0)
B42: БЛОК 5. Разовые затраты и комплаенс
B43: Юридический и комплаенс-аудит (NDPR, POPIA, KICA) | C43: фикс | D43: 25000 | E43: =IF($D43="","",$D43*INDEX(Допущения!$C$25:$G$30,MATCH($C43,Допущения!$B$25:$B$30,0),1)) | F43: 10000 | G43: 10000 | H43: 10000 | I43: 10000 | J43: =SUM(E43:I43) | L43: Регистрация NDPC, DPO, аудит. Далее ежегодный аудит $10k (А3)
B44: Пентест и аудит безопасности | C44: инфляция | D44: 12000 | E44: =IF($D44="","",$D44*INDEX(Допущения!$C$25:$G$30,MATCH($C44,Допущения!$B$25:$B$30,0),1)) | F44: =IF($D44="","",$D44*INDEX(Допущения!$C$25:$G$30,MATCH($C44,Допущения!$B$25:$B$30,0),2)) | G44: =IF($D44="","",$D44*INDEX(Допущения!$C$25:$G$30,MATCH($C44,Допущения!$B$25:$B$30,0),3)) | H44: =IF($D44="","",$D44*INDEX(Допущения!$C$25:$G$30,MATCH($C44,Допущения!$B$25:$B$30,0),4)) | I44: =IF($D44="","",$D44*INDEX(Допущения!$C$25:$G$30,MATCH($C44,Допущения!$B$25:$B$30,0),5)) | J44: =SUM(E44:I44) | L44: Ежегодный пентест, поверхность шире
B45: Миграция данных и интеграции при запуске | C45: фикс | D45: 0 | E45: =IF($D45="","",$D45*INDEX(Допущения!$C$25:$G$30,MATCH($C45,Допущения!$B$25:$B$30,0),1)) | F45: =IF($D45="","",$D45*INDEX(Допущения!$C$25:$G$30,MATCH($C45,Допущения!$B$25:$B$30,0),2)) | G45: =IF($D45="","",$D45*INDEX(Допущения!$C$25:$G$30,MATCH($C45,Допущения!$B$25:$B$30,0),3)) | H45: =IF($D45="","",$D45*INDEX(Допущения!$C$25:$G$30,MATCH($C45,Допущения!$B$25:$B$30,0),4)) | I45: =IF($D45="","",$D45*INDEX(Допущения!$C$25:$G$30,MATCH($C45,Допущения!$B$25:$B$30,0),5)) | J45: =SUM(E45:I45) | L45: Greenfield, миграции нет
B46: Обучение команды и найм | C46: фикс | D46: 20000 | E46: =IF($D46="","",$D46*INDEX(Допущения!$C$25:$G$30,MATCH($C46,Допущения!$B$25:$B$30,0),1)) | F46: 0 | G46: 0 | H46: 0 | I46: 0 | J46: =SUM(E46:I46) | L46: Найм 3 контракторов сверх заморозки (А6). Только Год 1
...

Sheet TCO-V3
B2: TCO на 5 лет - V3 Микросервисы по письму CTO: 40-50 сервисов, 3 кластера, Istio, Kafka, Oracle
B3: Заполняем колонки «Драйвер роста» и «База, $/год (Год 1)». Годы 1–5 считаются автоматически.
B5: Статья затрат | C5: Драйвер роста | D5: База, $/год (Год 1) | E5: Год 1 | F5: Год 2 | G5: Год 3 | H5: Год 4 | I5: Год 5 | J5: Итого 5 лет | K5: Доля | L5: Комментарий / источник
B6: БЛОК 1. Облачная инфраструктура (OpEx)
B7: Compute: ноды / контейнеры / serverless | C7: пользователи | D7: 48000 | E7: =IF($D7="","",$D7*INDEX(Допущения!$C$25:$G$30,MATCH($C7,Допущения!$B$25:$B$30,0),1)) | F7: =IF($D7="","",$D7*INDEX(Допущения!$C$25:$G$30,MATCH($C7,Допущения!$B$25:$B$30,0),2)) | G7: =IF($D7="","",$D7*INDEX(Допущения!$C$25:$G$30,MATCH($C7,Допущения!$B$25:$B$30,0),3)) | H7: =IF($D7="","",$D7*INDEX(Допущения!$C$25:$G$30,MATCH($C7,Допущения!$B$25:$B$30,0),4)) | I7: =IF($D7="","",$D7*INDEX(Допущения!$C$25:$G$30,MATCH($C7,Допущения!$B$25:$B$30,0),5)) | J7: =SUM(E7:I7) | L7: Основной кластер Kubernetes: ноды под 40-50 сервисов + Istio sidecars (А5)
B8: Управляемые БД (PostgreSQL, реплики) | C8: пользователи | D8: 18000 | E8: =IF($D8="","",$D8*INDEX(Допущения!$C$25:$G$30,MATCH($C8,Допущения!$B$25:$B$30,0),1)) | F8: =IF($D8="","",$D8*INDEX(Допущения!$C$25:$G$30,MATCH($C8,Допущения!$B$25:$B$30,0),2)) | G8: =IF($D8="","",$D8*INDEX(Допущения!$C$25:$G$30,MATCH($C8,Допущения!$B$25:$B$30,0),3)) | H8: =IF($D8="","",$D8*INDEX(Допущения!$C$25:$G$30,MATCH($C8,Допущения!$B$25:$B$30,0),4)) | I8: =IF($D8="","",$D8*INDEX(Допущения!$C$25:$G$30,MATCH($C8,Допущения!$B$25:$B$30,0),5)) | J8: =SUM(E8:I8) | L8: Self-hosted Oracle и PostgreSQL на ВМ и операторах (А5)
B9: Хранилище объектов и резервные копии | C9: пользователи | D9: 3600 | E9: =IF($D9="","",$D9*INDEX(Допущения!$C$25:$G$30,MATCH($C9,Допущения!$B$25:$B$30,0),1)) | F9: =IF($D9="","",$D9*INDEX(Допущения!$C$25:$G$30,MATCH($C9,Допущения!$B$25:$B$30,0),2)) | G9: =IF($D9="","",$D9*INDEX(Допущения!$C$25:$G$30,MATCH($C9,Допущения!$B$25:$B$30,0),3)) | H9: =IF($D9="","",$D9*INDEX(Допущения!$C$25:$G$30,MATCH($C9,Допущения!$B$25:$B$30,0),4)) | I9: =IF($D9="","",$D9*INDEX(Допущения!$C$25:$G$30,MATCH($C9,Допущения!$B$25:$B$30,0),5)) | J9: =SUM(E9:I9) | L9: Объектное хранилище, бэкапы трёх кластеров
B10: CDN и исходящий трафик | C10: пользователи | D10: 4800 | E10: =IF($D10="","",$D10*INDEX(Допущения!$C$25:$G$30,MATCH($C10,Допущения!$B$25:$B$30,0),1)) | F10: =IF($D10="","",$D10*INDEX(Допущения!$C$25:$G$30,MATCH($C10,Допущения!$B$25:$B$30,0),2)) | G10: =IF($D10="","",$D10*INDEX(Допущения!$C$25:$G$30,MATCH($C10,Допущения!$B$25:$B$30,0),3)) | H10: =IF($D10="","",$D10*INDEX(Допущения!$C$25:$G$30,MATCH($C10,Допущения!$B$25:$B$30,0),4)) | I10: =IF($D10="","",$D10*INDEX(Допущения!$C$25:$G$30,MATCH($C10,Допущения!$B$25:$B$30,0),5)) | J10: =SUM(E10:I10) | L10: CDN для фото и статики
B11: Очереди / стриминг (Kafka, SQS) | C11: пользователи | D11: 14400 | E11: =IF($D11="","",$D11*INDEX(Допущения!$C$25:$G$30,MATCH($C11,Допущения!$B$25:$B$30,0),1)) | F11: =IF($D11="","",$D11*INDEX(Допущения!$C$25:$G$30,MATCH($C11,Допущения!$B$25:$B$30,0),2)) | G11: =IF($D11="","",$D11*INDEX(Допущения!$C$25:$G$30,MATCH($C11,Допущения!$B$25:$B$30,0),3)) | H11: =IF($D11="","",$D11*INDEX(Допущения!$C$25:$G$30,MATCH($C11,Допущения!$B$25:$B$30,0),4)) | I11: =IF($D11="","",$D11*INDEX(Допущения!$C$25:$G$30,MATCH($C11,Допущения!$B$25:$B$30,0),5)) | J11: =SUM(E11:I11) | L11: Self-hosted Kafka, 3 брокера × 2 региона (А5)
B12: Резервный регион / DR | C12: пользователи | D12: 48000 | E12: =IF($D12="","",$D12*INDEX(Допущения!$C$25:$G$30,MATCH($C12,Допущения!$B$25:$B$30,0),1)) | F12: =IF($D12="","",$D12*INDEX(Допущения!$C$25:$G$30,MATCH($C12,Допущения!$B$25:$B$30,0),2)) | G12: =IF($D12="","",$D12*INDEX(Допущения!$C$25:$G$30,MATCH($C12,Допущения!$B$25:$B$30,0),3)) | H12: =IF($D12="","",$D12*INDEX(Допущения!$C$25:$G$30,MATCH($C12,Допущения!$B$25:$B$30,0),4)) | I12: =IF($D12="","",$D12*INDEX(Допущения!$C$25:$G$30,MATCH($C12,Допущения!$B$25:$B$30,0),5)) | J12: =SUM(E12:I12) | L12: Второй регион active-active, полная копия, RPO 0 (А5)
B13: Локальное размещение данных (NDPR, Нигерия) | C13: инфляция | D13: 30000 | E13: =IF($D13="","",$D13*INDEX(Допущения!$C$25:$G$30,MATCH($C13,Допущения!$B$25:$B$30,0),1)) | F13: =IF($D13="","",$D13*INDEX(Допущения!$C$25:$G$30,MATCH($C13,Допущения!$B$25:$B$30,0),2)) | G13: =IF($D13="","",$D13*INDEX(Допущения!$C$25:$G$30,MATCH($C13,Допущения!$B$25:$B$30,0),3)) | H13: =IF($D13="","",$D13*INDEX(Допущения!$C$25:$G$30,MATCH($C13,Допущения!$B$25:$B$30,0),4)) | I13: =IF($D13="","",$D13*INDEX(Допущения!$C$25:$G$30,MATCH($C13,Допущения!$B$25:$B$30,0),5)) | J13: =SUM(E13:I13) | L13: On-prem кластер в Нигерии: колокация и аренда оборудования (А5)
C14: фикс | E14: =IF($D14="","",$D14*INDEX(Допущения!$C$25:$G$30,MATCH($C14,Допущения!$B$25:$B$30,0),1)) | F14: =IF($D14="","",$D14*INDEX(Допущения!$C$25:$G$30,MATCH($C14,Допущения!$B$25:$B$30,0),2)) | G14: =IF($D14="","",$D14*INDEX(Допущения!$C$25:$G$30,MATCH($C14,Допущения!$B$25:$B$30,0),3)) | H14: =IF($D14="","",$D14*INDEX(Допущения!$C$25:$G$30,MATCH($C14,Допущения!$B$25:$B$30,0),4)) | I14: =IF($D14="","",$D14*INDEX(Допущения!$C$25:$G$30,MATCH($C14,Допущения!$B$25:$B$30,0),5)) | J14: =SUM(E14:I14) | L14: Своя статья
B15: Итого по блоку | E15: =SUM(E7:E14) | F15: =SUM(F7:F14) | G15: =SUM(G7:G14) | H15: =SUM(H7:H14) | I15: =SUM(I7:I14) | J15: =SUM(J7:J14) | K15: =IFERROR(J15/$J$51,0)
B17: БЛОК 2. Лицензии, SaaS и инструменты
B18: Observability (метрики, логи, трейсинг) | C18: пользователи | D18: 12000 | E18: =IF($D18="","",$D18*INDEX(Допущения!$C$25:$G$30,MATCH($C18,Допущения!$B$25:$B$30,0),1)) | F18: =IF($D18="","",$D18*INDEX(Допущения!$C$25:$G$30,MATCH($C18,Допущения!$B$25:$B$30,0),2)) | G18: =IF($D18="","",$D18*INDEX(Допущения!$C$25:$G$30,MATCH($C18,Допущения!$B$25:$B$30,0),3)) | H18: =IF($D18="","",$D18*INDEX(Допущения!$C$25:$G$30,MATCH($C18,Допущения!$B$25:$B$30,0),4)) | I18: =IF($D18="","",$D18*INDEX(Допущения!$C$25:$G$30,MATCH($C18,Допущения!$B$25:$B$30,0),5)) | J18: =SUM(E18:I18) | L18: Self-hosted Prometheus, Loki, Jaeger, Grafana: ВМ и хранилище (А5)
B19: CI/CD, репозиторий, артефакты | C19: инфляция | D19: 3600 | E19: =IF($D19="","",$D19*INDEX(Допущения!$C$25:$G$30,MATCH($C19,Допущения!$B$25:$B$30,0),1)) | F19: =IF($D19="","",$D19*INDEX(Допущения!$C$25:$G$30,MATCH($C19,Допущения!$B$25:$B$30,0),2)) | G19: =IF($D19="","",$D19*INDEX(Допущения!$C$25:$G$30,MATCH($C19,Допущения!$B$25:$B$30,0),3)) | H19: =IF($D19="","",$D19*INDEX(Допущения!$C$25:$G$30,MATCH($C19,Допущения!$B$25:$B$30,0),4)) | I19: =IF($D19="","",$D19*INDEX(Допущения!$C$25:$G$30,MATCH($C19,Допущения!$B$25:$B$30,0),5)) | J19: =SUM(E19:I19) | L19: GitHub, ArgoCD, реестр образов
B20: Безопасность: WAF, секреты, антифрод | C20: пользователи | D20: 6000 | E20: =IF($D20="","",$D20*INDEX(Допущения!$C$25:$G$30,MATCH($C20,Допущения!$B$25:$B$30,0),1)) | F20: =IF($D20="","",$D20*INDEX(Допущения!$C$25:$G$30,MATCH($C20,Допущения!$B$25:$B$30,0),2)) | G20: =IF($D20="","",$D20*INDEX(Допущения!$C$25:$G$30,MATCH($C20,Допущения!$B$25:$B$30,0),3)) | H20: =IF($D20="","",$D20*INDEX(Допущения!$C$25:$G$30,MATCH($C20,Допущения!$B$25:$B$30,0),4)) | I20: =IF($D20="","",$D20*INDEX(Допущения!$C$25:$G$30,MATCH($C20,Допущения!$B$25:$B$30,0),5)) | J20: =SUM(E20:I20) | L20: Istio mTLS, Vault, WAF
B21: WhatsApp Business API (подписка) | C21: инфляция | D21: 1200 | E21: =IF($D21="","",$D21*INDEX(Допущения!$C$25:$G$30,MATCH($C21,Допущения!$B$25:$B$30,0),1)) | F21: =IF($D21="","",$D21*INDEX(Допущения!$C$25:$G$30,MATCH($C21,Допущения!$B$25:$B$30,0),2)) | G21: =IF($D21="","",$D21*INDEX(Допущения!$C$25:$G$30,MATCH($C21,Допущения!$B$25:$B$30,0),3)) | H21: =IF($D21="","",$D21*INDEX(Допущения!$C$25:$G$30,MATCH($C21,Допущения!$B$25:$B$30,0),4)) | I21: =IF($D21="","",$D21*INDEX(Допущения!$C$25:$G$30,MATCH($C21,Допущения!$B$25:$B$30,0),5)) | J21: =SUM(E21:I21) | L21: BSP-подписка WhatsApp Business API
B22: Прочее ПО и подписки | C22: инфляция | D22: 2400 | E22: =IF($D22="","",$D22*INDEX(Допущения!$C$25:$G$30,MATCH($C22,Допущения!$B$25:$B$30,0),1)) | F22: =IF($D22="","",$D22*INDEX(Допущения!$C$25:$G$30,MATCH($C22,Допущения!$B$25:$B$30,0),2)) | G22: =IF($D22="","",$D22*INDEX(Допущения!$C$25:$G$30,MATCH($C22,Допущения!$B$25:$B$30,0),3)) | H22: =IF($D22="","",$D22*INDEX(Допущения!$C$25:$G$30,MATCH($C22,Допущения!$B$25:$B$30,0),4)) | I22: =IF($D22="","",$D22*INDEX(Допущения!$C$25:$G$30,MATCH($C22,Допущения!$B$25:$B$30,0),5)) | J22: =SUM(E22:I22) | L22: Трекер, дизайн
B23: Поддержка Oracle EE | C23: инфляция | D23: 20900 | E23: =IF($D23="","",$D23*INDEX(Допущения!$C$25:$G$30,MATCH($C23,Допущения!$B$25:$B$30,0),1)) | F23: =IF($D23="","",$D23*INDEX(Допущения!$C$25:$G$30,MATCH($C23,Допущения!$B$25:$B$30,0),2)) | G23: =IF($D23="","",$D23*INDEX(Допущения!$C$25:$G$30,MATCH($C23,Допущения!$B$25:$B$30,0),3)) | H23: =IF($D23="","",$D23*INDEX(Допущения!$C$25:$G$30,MATCH($C23,Допущения!$B$25:$B$30,0),4)) | I23: =IF($D23="","",$D23*INDEX(Допущения!$C$25:$G$30,MATCH($C23,Допущения!$B$25:$B$30,0),5)) | J23: =SUM(E23:I23) | L23: Поддержка Oracle EE: 22% от лицензии в год
B24: Итого по блоку | E24: =SUM(E18:E23) | F24: =SUM(F18:F23) | G24: =SUM(G18:G23) | H24: =SUM(H18:H23) | I24: =SUM(I18:I23) | J24: =SUM(J18:J23) | K24: =IFERROR(J24/$J$51,0)
B26: БЛОК 3. Транзакционные расходы (Buy / Partner)
B27: Комиссии платёжных провайдеров | C27: GMV | D27: 480000 | E27: =IF($D27="","",$D27*INDEX(Допущения!$C$25:$G$30,MATCH($C27,Допущения!$B$25:$B$30,0),1)) | F27: =IF($D27="","",$D27*INDEX(Допущения!$C$25:$G$30,MATCH($C27,Допущения!$B$25:$B$30,0),2)) | G27: =IF($D27="","",$D27*INDEX(Допущения!$C$25:$G$30,MATCH($C27,Допущения!$B$25:$B$30,0),3)) | H27: =IF($D27="","",$D27*INDEX(Допущения!$C$25:$G$30,MATCH($C27,Допущения!$B$25:$B$30,0),4)) | I27: =IF($D27="","",$D27*INDEX(Допущения!$C$25:$G$30,MATCH($C27,Допущения!$B$25:$B$30,0),5)) | J27: =SUM(E27:I27) | L27: 2,0% GMV all-in: M-Pesa Daraja (KE), Flutterwave и Paystack (NG). Лимит CFO 2,5% (А6). Одинаково для всех вариантов
B28: SMS-уведомления | C28: заказы | D28: 90000 | E28: =IF($D28="","",$D28*INDEX(Допущения!$C$25:$G$30,MATCH($C28,Допущения!$B$25:$B$30,0),1)) | F28: =IF($D28="","",$D28*INDEX(Допущения!$C$25:$G$30,MATCH($C28,Допущения!$B$25:$B$30,0),2)) | G28: =IF($D28="","",$D28*INDEX(Допущения!$C$25:$G$30,MATCH($C28,Допущения!$B$25:$B$30,0),3)) | H28: =IF($D28="","",$D28*INDEX(Допущения!$C$25:$G$30,MATCH($C28,Допущения!$B$25:$B$30,0),4)) | I28: =IF($D28="","",$D28*INDEX(Допущения!$C$25:$G$30,MATCH($C28,Допущения!$B$25:$B$30,0),5)) | J28: =SUM(E28:I28) | L28: 3 SMS на заказ × $0,025
B29: WhatsApp-сообщения (за диалог) | C29: заказы | D29: 18000 | E29: =IF($D29="","",$D29*INDEX(Допущения!$C$25:$G$30,MATCH($C29,Допущения!$B$25:$B$30,0),1)) | F29: =IF($D29="","",$D29*INDEX(Допущения!$C$25:$G$30,MATCH($C29,Допущения!$B$25:$B$30,0),2)) | G29: =IF($D29="","",$D29*INDEX(Допущения!$C$25:$G$30,MATCH($C29,Допущения!$B$25:$B$30,0),3)) | H29: =IF($D29="","",$D29*INDEX(Допущения!$C$25:$G$30,MATCH($C29,Допущения!$B$25:$B$30,0),4)) | I29: =IF($D29="","",$D29*INDEX(Допущения!$C$25:$G$30,MATCH($C29,Допущения!$B$25:$B$30,0),5)) | J29: =SUM(E29:I29) | L29: 1 utility-диалог WhatsApp на заказ × $0,015
B30: Логистика: интеграции и комиссии партнёров | C30: заказы | D30: 180000 | E30: =IF($D30="","",$D30*INDEX(Допущения!$C$25:$G$30,MATCH($C30,Допущения!$B$25:$B$30,0),1)) | F30: =IF($D30="","",$D30*INDEX(Допущения!$C$25:$G$30,MATCH($C30,Допущения!$B$25:$B$30,0),2)) | G30: =IF($D30="","",$D30*INDEX(Допущения!$C$25:$G$30,MATCH($C30,Допущения!$B$25:$B$30,0),3)) | H30: =IF($D30="","",$D30*INDEX(Допущения!$C$25:$G$30,MATCH($C30,Допущения!$B$25:$B$30,0),4)) | I30: =IF($D30="","",$D30*INDEX(Допущения!$C$25:$G$30,MATCH($C30,Допущения!$B$25:$B$30,0),5)) | J30: =SUM(E30:I30) | L30: Сбор API Sendbox и Sendy $0,15 на заказ. Тариф доставки платит покупатель
C31: фикс | E31: =IF($D31="","",$D31*INDEX(Допущения!$C$25:$G$30,MATCH($C31,Допущения!$B$25:$B$30,0),1)) | F31: =IF($D31="","",$D31*INDEX(Допущения!$C$25:$G$30,MATCH($C31,Допущения!$B$25:$B$30,0),2)) | G31: =IF($D31="","",$D31*INDEX(Допущения!$C$25:$G$30,MATCH($C31,Допущения!$B$25:$B$30,0),3)) | H31: =IF($D31="","",$D31*INDEX(Допущения!$C$25:$G$30,MATCH($C31,Допущения!$B$25:$B$30,0),4)) | I31: =IF($D31="","",$D31*INDEX(Допущения!$C$25:$G$30,MATCH($C31,Допущения!$B$25:$B$30,0),5)) | J31: =SUM(E31:I31) | L31: Своя статья
B32: Итого по блоку | E32: =SUM(E27:E31) | F32: =SUM(F27:F31) | G32: =SUM(G27:G31) | H32: =SUM(H27:H31) | I32: =SUM(I27:I31) | J32: =SUM(J27:J31) | K32: =IFERROR(J32/$J$51,0)
B34: БЛОК 4. Команда (ФОТ)
B35: Разработка (FTE × годовая ставка) | C35: ФОТ | D35: 720000 | E35: =IF($D35="","",$D35*INDEX(Допущения!$C$25:$G$30,MATCH($C35,Допущения!$B$25:$B$30,0),1)) | F35: =IF($D35="","",$D35*INDEX(Допущения!$C$25:$G$30,MATCH($C35,Допущения!$B$25:$B$30,0),2)) | G35: =IF($D35="","",$D35*INDEX(Допущения!$C$25:$G$30,MATCH($C35,Допущения!$B$25:$B$30,0),3)) | H35: =IF($D35="","",$D35*INDEX(Допущения!$C$25:$G$30,MATCH($C35,Допущения!$B$25:$B$30,0),4)) | I35: =IF($D35="","",$D35*INDEX(Допущения!$C$25:$G$30,MATCH($C35,Допущения!$B$25:$B$30,0),5)) | J35: =SUM(E35:I35) | L35: 12 разработчиков: ядро, своя логистика (4), платёжная оркестрация (2) (А5)
B36: DevOps / SRE | C36: ФОТ | D36: 240000 | E36: =IF($D36="","",$D36*INDEX(Допущения!$C$25:$G$30,MATCH($C36,Допущения!$B$25:$B$30,0),1)) | F36: =IF($D36="","",$D36*INDEX(Допущения!$C$25:$G$30,MATCH($C36,Допущения!$B$25:$B$30,0),2)) | G36: =IF($D36="","",$D36*INDEX(Допущения!$C$25:$G$30,MATCH($C36,Допущения!$B$25:$B$30,0),3)) | H36: =IF($D36="","",$D36*INDEX(Допущения!$C$25:$G$30,MATCH($C36,Допущения!$B$25:$B$30,0),4)) | I36: =IF($D36="","",$D36*INDEX(Допущения!$C$25:$G$30,MATCH($C36,Допущения!$B$25:$B$30,0),5)) | J36: =SUM(E36:I36) | L36: 4 платформенных инженера: multi-cluster, Istio, Kafka, Oracle DBA
B37: Поддержка и дежурства 24/7 | C37: ФОТ | D37: 96000 | E37: =IF($D37="","",$D37*INDEX(Допущения!$C$25:$G$30,MATCH($C37,Допущения!$B$25:$B$30,0),1)) | F37: =IF($D37="","",$D37*INDEX(Допущения!$C$25:$G$30,MATCH($C37,Допущения!$B$25:$B$30,0),2)) | G37: =IF($D37="","",$D37*INDEX(Допущения!$C$25:$G$30,MATCH($C37,Допущения!$B$25:$B$30,0),3)) | H37: =IF($D37="","",$D37*INDEX(Допущения!$C$25:$G$30,MATCH($C37,Допущения!$B$25:$B$30,0),4)) | I37: =IF($D37="","",$D37*INDEX(Допущения!$C$25:$G$30,MATCH($C37,Допущения!$B$25:$B$30,0),5)) | J37: =SUM(E37:I37) | L37: Выделенная ротация 24/7 на трёх кластерах
B38: Архитектура и менеджмент | C38: ФОТ | D38: 150000 | E38: =IF($D38="","",$D38*INDEX(Допущения!$C$25:$G$30,MATCH($C38,Допущения!$B$25:$B$30,0),1)) | F38: =IF($D38="","",$D38*INDEX(Допущения!$C$25:$G$30,MATCH($C38,Допущения!$B$25:$B$30,0),2)) | G38: =IF($D38="","",$D38*INDEX(Допущения!$C$25:$G$30,MATCH($C38,Допущения!$B$25:$B$30,0),3)) | H38: =IF($D38="","",$D38*INDEX(Допущения!$C$25:$G$30,MATCH($C38,Допущения!$B$25:$B$30,0),4)) | I38: =IF($D38="","",$D38*INDEX(Допущения!$C$25:$G$30,MATCH($C38,Допущения!$B$25:$B$30,0),5)) | J38: =SUM(E38:I38) | L38: CTO и SA, доля на платформу
C39: фикс | E39: =IF($D39="","",$D39*INDEX(Допущения!$C$25:$G$30,MATCH($C39,Допущения!$B$25:$B$30,0),1)) | F39: =IF($D39="","",$D39*INDEX(Допущения!$C$25:$G$30,MATCH($C39,Допущения!$B$25:$B$30,0),2)) | G39: =IF($D39="","",$D39*INDEX(Допущения!$C$25:$G$30,MATCH($C39,Допущения!$B$25:$B$30,0),3)) | H39: =IF($D39="","",$D39*INDEX(Допущения!$C$25:$G$30,MATCH($C39,Допущения!$B$25:$B$30,0),4)) | I39: =IF($D39="","",$D39*INDEX(Допущения!$C$25:$G$30,MATCH($C39,Допущения!$B$25:$B$30,0),5)) | J39: =SUM(E39:I39) | L39: Своя статья
B40: Итого по блоку | E40: =SUM(E35:E39) | F40: =SUM(F35:F39) | G40: =SUM(G35:G39) | H40: =SUM(H35:H39) | I40: =SUM(I35:I39) | J40: =SUM(J35:J39) | K40: =IFERROR(J40/$J$51,0)
B42: БЛОК 5. Разовые затраты и комплаенс
B43: Юридический и комплаенс-аудит (NDPR, POPIA, KICA) | C43: фикс | D43: 25000 | E43: =IF($D43="","",$D43*INDEX(Допущения!$C$25:$G$30,MATCH($C43,Допущения!$B$25:$B$30,0),1)) | F43: 10000 | G43: 10000 | H43: 10000 | I43: 10000 | J43: =SUM(E43:I43) | L43: Регистрация NDPC, DPO, аудит. Далее ежегодный аудит $10k (А3)
B44: Пентест и аудит безопасности | C44: инфляция | D44: 15000 | E44: =IF($D44="","",$D44*INDEX(Допущения!$C$25:$G$30,MATCH($C44,Допущения!$B$25:$B$30,0),1)) | F44: =IF($D44="","",$D44*INDEX(Допущения!$C$25:$G$30,MATCH($C44,Допущения!$B$25:$B$30,0),2)) | G44: =IF($D44="","",$D44*INDEX(Допущения!$C$25:$G$30,MATCH($C44,Допущения!$B$25:$B$30,0),3)) | H44: =IF($D44="","",$D44*INDEX(Допущения!$C$25:$G$30,MATCH($C44,Допущения!$B$25:$B$30,0),4)) | I44: =IF($D44="","",$D44*INDEX(Допущения!$C$25:$G$30,MATCH($C44,Допущения!$B$25:$B$30,0),5)) | J44: =SUM(E44:I44) | L44: Ежегодный пентест, 40-50 сервисов и mesh
